Workbook

Sheet 00_Bìa
A1: FPTPost – Bộ đặc tả yêu cầu và thiết kế hệ thống
A2: Nền tảng giao hàng cowork ngang hàng (P2P) • Tài liệu đặc tả nghiệp vụ • Ngôn ngữ: tiếng Việt • Phiên bản 1.0
A4: 1. Thông tin tài liệu
A5: Dự án | B5: FPTPost
A6: Môn học | B6: SBA301 – Tích hợp ứng dụng trang đơn với Spring Boot
A7: Nhóm | B7: 6 thành viên (Lead: Lư Hữu Luân), 5 tuần, 5 sprint (10/10/2026 – 14/11/2026)
A8: Ngày lập | B8: 08/10/2026
A9: Trạng thái | B9: Dự thảo v1.0 – chờ nhóm rà soát
A10: Tài liệu đi kèm | B10: FPTPost – Tài liệu thiết kế hệ thống (SPEC): tài liệu Claude Docs, xuất được sang Word/PDF; thiết kế kỹ thuật cho nhóm phát triển, không lặp lại nội dung của bảng tính này
A12: 2. Lịch sử phiên bản
A13: Phiên bản | B13: Nội dung thay đổi | C13: Ngày | D13: Người lập
A14: 1.0 | B14: Khởi tạo bộ đặc tả: BR, UC, tham số, dữ liệu, API, màn hình, đánh giá VNPay, kế hoạch | C14: 08/10/2026 | D14: Nhóm FPTPost
A16: 3. Số liệu tổng hợp (tính tự động từ các sheet)
A17: Chỉ tiêu | B17: Diễn giải | C17: Giá trị
A18: Tổng số BR | B18: Mọi loại yêu cầu nghiệp vụ | C18: =COUNTIF('03_BR'!A:A,"BR-*") -> 286
A19: Functional BR | B19: Yêu cầu chức năng | C19: =COUNTIF('03_BR'!B:B,"Functional BR") -> 124
A20: Non-functional BR | B20: Yêu cầu phi chức năng | C20: =COUNTIF('03_BR'!B:B,"Non-functional BR") -> 41
A21: Business Rule | B21: Quy tắc nghiệp vụ | C21: =COUNTIF('03_BR'!B:B,"Business Rule") -> 85
A22: Business Constraint | B22: Ràng buộc | C22: =COUNTIF('03_BR'!B:B,"Business Constraint") -> 22
A23: Business Goal | B23: Mục tiêu kinh doanh | C23: =COUNTIF('03_BR'!B:B,"Business Goal") -> 14
A24: BR mức Must / Should / Could | B24: Theo MoSCoW | C24: =COUNTIF('03_BR'!H:H,"Must")&" / "&COUNTIF('03_BR'!H:H,"Should")&" / "&COUNTIF('03_BR'!H:H,"Could") -> 213 / 50 / 23
A25: Tổng số Use Case | B25: UC mô tả ở sheet 04 | C25: =COUNTIF('04_UC'!A:A,"UC-*") -> 63
A26: UC mức Must / Should / Could | B26: Theo MoSCoW | C26: =COUNTIF('04_UC'!F:F,"Must")&" / "&COUNTIF('04_UC'!F:F,"Should")&" / "&COUNTIF('04_UC'!F:F,"Could") -> 50 / 6 / 7
A27: Tổng giờ ước lượng UC (BE+FE) | B27: Gồm cả Could | C27: =SUM('04_UC'!Q:Q) -> 474
A28: Giờ ước lượng UC Must + Should | B28: Không gồm Could | C28: =SUMIFS('04_UC'!Q:Q,'04_UC'!F:F,"<>Could") -> 420
A29: Tham số nghiệp vụ | B29: Sheet 06 | C29: =COUNTIF('06_Tham_số'!A:A,"PRM-*") -> 109
A30: Thực thể dữ liệu | B30: Sheet 09 | C30: =COUNTIF('09_Dữ_liệu'!A:A,"DB-*") -> 55
A31: Endpoint API | B31: Sheet 10 | C31: =COUNTIF('10_API'!A:A,"API-*") -> 167
A32: Màn hình | B32: Sheet 11 | C32: =COUNTIF('11_Màn_hình'!A:A,"SCR-*") -> 64
A33: Rủi ro đã nhận diện | B33: Sheet 16 | C33: =COUNTIF('16_Rủi_ro'!A:A,"R-*") -> 24
A34: UC chưa có BR chức năng/quy tắc | B34: Kiểm tra độ phủ, mong đợi = 0 | C34: =SUMPRODUCT(--(('05_Truy_vết'!E5:E67+'05_Truy_vết'!G5:G67)=0)) -> 0
A35: Mức sử dụng công suất toàn đội | B35: Từ sheet 13 (UC + việc chung + họp) | C35: ='13_Kế_hoạch_Nhân_sự'!G21 -> 0.97777778
A37: 4. Danh mục sheet
A38: Sheet | B38: Nội dung
A39: 01_Tổng_quan | B39: Tầm nhìn, phạm vi, giá trị khác biệt, bên liên quan, giả định
A40: 02_Tác_nhân_Phân_quyền | B40: Tác nhân và ma trận phân quyền theo vai trò
A41: 03_BR | B41: Toàn bộ BR (Functional, Non-functional, Business Rule, Constraint, Goal) kèm tiêu chí nghiệm thu
A42: 04_UC | B42: 63 Use Case: luồng chính, ngoại lệ, người phụ trách, ước lượng giờ, sprint
A43: 05_Truy_vết | B43: Ma trận truy vết UC ↔ BR ↔ màn hình ↔ API và số liệu độ phủ
A44: 06_Tham_số | B44: Tham số nghiệp vụ có thể cấu hình (mọi con số trong BR lấy từ đây)
...

Sheet 01_Tổng_quan
A1: Tổng quan dự án
A2: Tầm nhìn, phạm vi, giá trị khác biệt, bên liên quan, giả định
A4: 1. Thông tin dự án
A5: Tên dự án | B5: FPTPost – nền tảng giao hàng cowork ngang hàng (P2P)
A6: Mã dự án | B6: FPTPOST
A7: Mô tả ngắn | B7: Nền tảng kết nối người có hàng cần gửi với người sẵn sàng giao hàng tiện đường, không qua nhà phân phối; nền tảng chịu trách nhiệm xác minh, ký quỹ, theo dõi và thanh toán với phí hoa hồng thấp.
A8: Môn học | B8: SBA301 – Tích hợp ứng dụng trang đơn với Spring Boot (đồ án nhóm chiếm 25% điểm; phải bao phủ toàn bộ CLO)
A9: Thời gian | B9: 5 tuần (10/10/2026 – 14/11/2026), chia 5 sprint, mỗi sprint 1 tuần
A10: Quy mô nhóm | B10: 6 thành viên (Lead: Lư Hữu Luân), phụ trách theo lát cắt dọc (backend + frontend)
A11: Công nghệ chính | B11: Java 21, Spring Boot 3, Spring Security (JWT), Spring Data JPA/Hibernate với SQL Server, Spring Data MongoDB, ReactJS (Node 21) + React-Bootstrap, WebSocket, Docker
A12: Thanh toán | B12: VNPay (sandbox) cho thu tiền và hoàn tiền; rút tiền qua PayoutProvider (xem sheet 12_VNPay)
A13: Phiên bản tài liệu | B13: 1.0 – khởi tạo (08/10/2026)
A14: Phạm vi địa lý khởi điểm (giả định) | B14: Cộng đồng FPT (sinh viên, giảng viên, nhân viên) và khu vực lân cận campus; kiến trúc cho phép mở rộng toàn thành phố
A16: 2. Tầm nhìn và vấn đề
A17: Tầm nhìn | B17: Biến mỗi chuyến đi hằng ngày thành một cơ hội giao hàng: người có hàng gửi nhanh và rẻ hơn, người đi đường có thêm thu nhập, và mọi giao dịch đều minh bạch, được bảo chứng bởi nền tảng.
A18: Vấn đề cần giải quyết | B18: Chi phí và thời gian giao hàng qua đơn vị vận chuyển truyền thống cao; nhiều người có sẵn chuyến đi nhưng thiếu kênh an toàn để nhận giao hàng; giao dịch tự phát trên mạng xã hội thiếu niềm tin, không theo dõi được và dễ lừa đảo.
A20: 3. Giá trị khác biệt của FPTPost
A21: Điểm khác biệt | B21: Mô tả | C21: UC chính | D21: BR tham chiếu
A22: Giao tiện đường (trip-based matching) | B22: Người giao đăng chuyến đi; hệ thống gợi ý đơn nằm dọc tuyến, giảm chi phí cho cả hai bên. | C22: UC-21, UC-22, UC-23 | D22: BR-F ghép đơn; BR-R điều kiện ghép đơn–chuyến
A23: Ký quỹ và xác nhận bằng OTP/QR | B23: Tiền được giữ cho đến khi người nhận xác nhận, giải quyết bài toán niềm tin giữa người lạ. | C23: UC-35, UC-36, UC-25, UC-28 | D23: BR-R điều kiện ký quỹ và giải ngân
A24: Điểm uy tín và hạng thành viên | B24: Hạng quyết định hoa hồng, hạn mức đơn và quyền nhận hàng giá trị cao. | C24: UC-49, UC-48 | D24: BR-R công thức điểm uy tín, hạng
A25: Hoa hồng thấp, minh bạch | B25: Hoa hồng 4–8% phí giao, chỉ thu từ người giao; người gửi không trả phí nền tảng. | C25: UC-36, UC-46 | D25: BR-R hoa hồng theo hạng
A26: Thương lượng giá có biên | B26: Người giao chào giá trong biên quanh giá gợi ý, tránh chặt chém và tránh giá phi thực tế. | C26: UC-18, UC-19 | D26: BR-R biên giá chào
A27: Giao tiếp sức (relay) | B27: Chia đơn đường dài thành nhiều chặng, mỗi người giao một đoạn tiện đường (giai đoạn mở rộng). | C27: UC-32, UC-33 | D27: BR-R quy tắc đơn tiếp sức
A28: Bằng chứng giao nhận và Quỹ bảo đảm | B28: Ảnh, mã xác nhận, vị trí làm chứng cứ; quỹ bảo đảm bồi thường cho đơn có bảo hiểm. | C28: UC-25, UC-28, UC-52 | D28: BR-R điều kiện bồi thường
A29: Cộng đồng tin cậy FPT | B29: Huy hiệu Cộng đồng FPT, điểm hẹn bàn giao an toàn quanh campus. | C29: UC-07, UC-33 | D29: BR-R huy hiệu cộng đồng FPT
A31: 4. Mô hình doanh thu và chi phí (trích từ tham số)
A32: Nguồn thu chính | B32: Hoa hồng thu từ người giao, tính trên phí giao: Tân binh 8% [PRM-042], Đồng 7% [PRM-043], Bạc 6% [PRM-044], Vàng 5% [PRM-045], Kim cương 4% [PRM-046].
A33: Người gửi | B33: Không trả phí nền tảng; chỉ trả phí giao và bảo hiểm tùy chọn (1% [PRM-047] giá trị khai báo).
A34: Phí rút tiền | B34: Miễn phí 4 lần [PRM-062]; từ lần kế tiếp 5.000đ [PRM-063]/lần.
A35: Quỹ bảo đảm | B35: Trích 10% [PRM-049] hoa hồng và toàn bộ phí bảo hiểm để bồi thường đơn có bảo hiểm.
A36: Khuyến mãi | B36: Chi phí do nền tảng chịu, không làm giảm thu nhập người giao.
A37: Mô phỏng | B37: Xem sheet 07 để thử các kịch bản giá, hoa hồng và dòng tiền.
A39: 5. Phạm vi
A40: Giai đoạn / loại | B40: Nội dung
A41: Giai đoạn 1 (MVP – Must) | B41: Tài khoản, KYC, tạo đơn, sàn đơn, nhận đơn/chào giá, chat, ký quỹ qua ví và VNPay, lấy/giao bằng QR/OTP, theo dõi, giải ngân, hoàn tiền, rút tiền, khiếu nại, kiểm duyệt, quản trị cơ bản.
A42: Giai đoạn 2 (Should) | B42: Chuyến đi và gợi ý ghép đơn–chuyến, hoàn tiền về nguồn VNPay, đối soát, thu nhập và thống kê, nhật ký kiểm toán, SOS.
A43: Giai đoạn 3 (Could – làm khi còn công suất) | B43: Mời trực tiếp, khuyến mãi, huy hiệu/giới thiệu bạn bè, gộp đơn, giao tiếp sức, Web Push.
A44: Ngoài phạm vi | B44: Ứng dụng di động native (chỉ web responsive/PWA nếu còn thời gian).
B45: Thu hộ tiền hàng (COD) và thanh toán tiền mặt cho phí giao.
...

Sheet 02_Tác_nhân_Phân_quyền
A1: Tác nhân và phân quyền
A2: Danh sách tác nhân; ma trận phân quyền theo vai trò (RBAC)
A4: 1. Danh sách tác nhân
A5: Mã | B5: Tác nhân | C5: Loại | D5: Mô tả | F5: Mục tiêu chính | H5: UC tham gia
A6: A01 | B6: Khách vãng lai (Guest) | C6: Người dùng | D6: Người chưa đăng nhập, truy cập trang công khai và ước tính giá. | F6: Tìm hiểu dịch vụ, ước tính giá, đăng ký. | H6: UC-01
A7: A02 | B7: Người gửi (Sender) | C7: Người dùng | D7: Cá nhân có hàng cần gửi; tạo đơn, chọn người giao, ký quỹ và theo dõi. | F7: Gửi hàng nhanh, rẻ, an toàn và minh bạch. | H7: UC-11, UC-12, UC-14, UC-15, UC-17, UC-18, UC-19, UC-20, UC-21, UC-25, UC-27, UC-29, UC-30, UC-32, UC-35, UC-37, UC-44, UC-51
A8: A03 | B8: Người giao (Courier / Cowork) | C8: Người dùng | D8: Cá nhân đã xác minh, nhận giao hàng tiện đường hoặc theo đơn để có thêm thu nhập. | F8: Có đơn phù hợp tuyến, thu nhập rõ ràng, rút tiền dễ. | H8: UC-15, UC-16, UC-17, UC-18, UC-19, UC-20, UC-21, UC-22, UC-23, UC-25, UC-26, UC-28, UC-29, UC-30, UC-31, UC-32, UC-33, UC-36, UC-39, UC-40, UC-51, UC-61
A9: A04 | B9: Người nhận (Recipient) | C9: Người dùng ngoài hệ thống | D9: Người nhận hàng; không cần tài khoản, tương tác qua liên kết theo dõi và OTP/QR. | F9: Biết hàng đang ở đâu và nhận đúng hàng. | H9: UC-27, UC-28
A10: A05 | B10: Kiểm duyệt viên (Moderator) | C10: Nhân sự nội bộ | D10: Duyệt KYC, kiểm duyệt đơn, xử lý khiếu nại và báo cáo vi phạm. | F10: Giữ nền tảng an toàn, xử lý tranh chấp công bằng. | H10: UC-09, UC-29, UC-51, UC-54, UC-55
A11: A06 | B11: Quản trị viên (Admin) | C11: Nhân sự nội bộ | D11: Cấu hình hệ thống, duyệt rút tiền, đối soát, quản lý người dùng và báo cáo. | F11: Vận hành ổn định, kiểm soát rủi ro tài chính. | H11: UC-41, UC-43, UC-45, UC-46, UC-52, UC-56, UC-57, UC-58, UC-59, UC-60, UC-63
A12: A07 | B12: Hệ thống (Scheduler/System) | C12: Hệ thống | D12: Tác nhân tự động theo thời gian hoặc sự kiện: hết hạn, giải ngân, đối soát, tính điểm. | F12: Thực thi quy tắc nghiệp vụ chính xác, đúng hạn. | H12: UC-21, UC-36, UC-37, UC-42, UC-43, UC-49, UC-54, UC-63
A13: A08 | B13: Cổng thanh toán VNPay | C13: Hệ thống ngoài | D13: Cung cấp thanh toán trực tuyến, IPN, truy vấn và hoàn tiền. | F13: Thu tiền và hoàn tiền an toàn. | H13: UC-34, UC-35, UC-37, UC-42
A14: A09 | B14: Dịch vụ bản đồ và định tuyến | C14: Hệ thống ngoài | D14: OpenStreetMap/Leaflet cho hiển thị, dịch vụ định tuyến và geocoding. | F14: Tính quãng đường và hiển thị bản đồ. | H14: UC-11, UC-12, UC-22
A15: A10 | B15: Dịch vụ Email/SMS | C15: Hệ thống ngoài | D15: Gửi OTP và thông báo qua email/SMS (SMTP, SMS giả lập khi phát triển). | F15: Gửi thông báo tin cậy. | H15: UC-01, UC-02, UC-05, UC-53
A16: A11 | B16: Dịch vụ chi trả (PayoutProvider) | C16: Hệ thống ngoài/nội bộ | D16: Mock, thủ công hoặc nhà cung cấp chi hộ thật dùng để chuyển tiền rút về ngân hàng. | F16: Chuyển tiền rút cho người giao. | H16: UC-41
A18: 2. Ma trận phân quyền (RBAC)
A19: STT | B19: Chức năng | C19: UC | D19: Khách | E19: Người gửi | F19: Người giao | G19: Người nhận | H19: Kiểm duyệt | I19: Admin
A20: 1 | B20: Xem trang giới thiệu, điều khoản, FAQ | C20: — | D20: ✔ | E20: ✔ | F20: ✔ | G20: ✔ | H20: ✔ | I20: ✔
A21: 2 | B21: Ước tính giá giao hàng | C21: UC-11 | D21: ✔ | E21: ✔ | F21: ✔ | G21: — | H21: — | I21: ✔
A22: 3 | B22: Đăng ký tài khoản, xác thực OTP | C22: UC-01, UC-02 | D22: ✔ | E22: — | F22: — | G22: — | H22: — | I22: —
A23: 4 | B23: Đăng nhập, đăng xuất, quên/đổi mật khẩu | C23: UC-03..06 | D23: ✔ | E23: ✔ | F23: ✔ | G23: — | H23: ✔ | I23: ✔
A24: 5 | B24: Quản lý hồ sơ cá nhân, sổ địa chỉ | C24: UC-07 | D24: — | E24: Của mình | F24: Của mình | G24: — | H24: Của mình | I24: Của mình
A25: 6 | B25: Gửi hồ sơ xác minh KYC | C25: UC-08 | D25: — | E25: ✔ | F25: ✔ | G25: — | H25: — | I25: —
A26: 7 | B26: Duyệt hồ sơ KYC | C26: UC-09 | D26: — | E26: — | F26: — | G26: — | H26: ✔ | I26: ✔
A27: 8 | B27: Đăng ký làm Người giao | C27: UC-10 | D27: — | E27: ✔ | F27: — | G27: — | H27: — | I27: —
A28: 9 | B28: Tạo, sửa đơn | C28: UC-12, UC-14 | D28: — | E28: Của mình | F28: — | G28: — | H28: — | I28: —
A29: 10 | B29: Hủy đơn | C29: UC-15 | D29: — | E29: Của mình | F29: Của mình | G29: — | H29: — | I29: ✔
A30: 11 | B30: Xem danh sách và chi tiết đơn | C30: UC-13 | D30: — | E30: Của mình | F30: Của mình | G30: — | H30: ✔ | I30: ✔
A31: 12 | B31: Duyệt sàn đơn | C31: UC-16 | D31: — | E31: — | F31: ✔ | G31: — | H31: — | I31: ✔
... A64: 45 | B64: Xem trạng thái tác vụ định kỳ | C64: UC-63 | D64: — | E64: — | F64: — | G64: — | H64: — | I64: ✔
B66: Chú giải: ✔ = được thực hiện; Của mình = chỉ dữ liệu thuộc quyền; Một phần = chỉ một số thao tác hoặc dữ liệu; Đề xuất = chỉ được đề xuất, Admin quyết định; — = không có quyền.

Sheet 03_BR
A1: Danh mục BR – Business Requirements
A2: Functional • Non-functional • Business Rule • Business Constraint • Business Goal | Mọi giá trị số lấy từ sheet 06_Tham_số (mã trong [PRM-xxx])
A4: Mã BR | B4: Loại BR | C4: Phân hệ | D4: Tiêu đề | E4: Mô tả yêu cầu | F4: Tác nhân / Chủ thể | G4: UC liên quan | H4: Ưu tiên | I4: Pha | J4: Tiêu chí nghiệm thu / đo lường | K4: Tham số liên quan | L4: Căn cứ | M4: Trạng thái
A5: BR-F-001 | B5: Functional BR | C5: AUTH | D5: Đăng ký tài khoản | E5: Hệ thống cho phép khách đăng ký tài khoản bằng họ tên, email, số điện thoại và mật khẩu sau khi đồng ý Điều khoản sử dụng và Chính sách dữ liệu cá nhân (có ghi nhận phiên bản và thời điểm đồng ý). | F5: Khách | G5: UC-01 | H5: Must | I5: Pha 1 | J5: Đăng ký hợp lệ tạo tài khoản trạng thái Chờ xác thực và lưu bản ghi đồng ý chính sách. | L5: Nhu cầu người dùng | M5: Dự thảo
A6: BR-F-002 | B6: Functional BR | C6: AUTH | D6: Xác thực OTP | E6: Hệ thống gửi OTP đến email hoặc số điện thoại và cho phép người dùng xác thực để kích hoạt tài khoản. | F6: Người dùng | G6: UC-02 | H6: Must | I6: Pha 1 | J6: Nhập đúng OTP: tài khoản chuyển Hoạt động; sai/hết hạn: báo lỗi đúng mã. | L6: Nhu cầu người dùng | M6: Dự thảo
A7: BR-F-003 | B7: Functional BR | C7: AUTH | D7: Đăng nhập và cấp token | E7: Hệ thống cho phép đăng nhập bằng email hoặc số điện thoại và mật khẩu, trả về Access Token và Refresh Token theo cơ chế JWT. | F7: Người dùng | G7: UC-03 | H7: Must | I7: Pha 1 | J7: Đăng nhập đúng trả token hợp lệ; sai trả 401 không tiết lộ trường nào sai. | L7: Nhu cầu người dùng | M7: Dự thảo
A8: BR-F-004 | B8: Functional BR | C8: AUTH | D8: Đăng nhập nhanh bằng Google | E8: Hệ thống cho phép đăng nhập hoặc đăng ký nhanh bằng tài khoản Google (OAuth2), tự động nhận diện email thuộc tên miền FPT để cấp huy hiệu cộng đồng. | F8: Người dùng | G8: UC-03, UC-07 | H8: Could | I8: Pha 3 | J8: Đăng nhập Google tạo/liên kết tài khoản đúng email; email @fpt.edu.vn nhận huy hiệu. | L8: Nhu cầu người dùng | M8: Dự thảo
A9: BR-F-005 | B9: Functional BR | C9: AUTH | D9: Đăng xuất và quản lý thiết bị | E9: Hệ thống cho phép đăng xuất, xem danh sách thiết bị/phiên đang đăng nhập và thu hồi từng phiên từ xa. | F9: Người dùng | G9: UC-04 | H9: Must | I9: Pha 1 | J9: Thu hồi phiên: token của phiên đó bị vô hiệu ngay. | L9: Nhu cầu người dùng | M9: Dự thảo
A10: BR-F-006 | B10: Functional BR | C10: AUTH | D10: Quên và đặt lại mật khẩu | E10: Hệ thống cho phép đặt lại mật khẩu bằng OTP gửi tới email hoặc số điện thoại đã đăng ký; sau khi đặt lại, mọi phiên cũ bị thu hồi. | F10: Người dùng | G10: UC-05 | H10: Must | I10: Pha 1 | J10: Đặt lại thành công: đăng nhập được bằng mật khẩu mới, phiên cũ mất hiệu lực. | L10: Nhu cầu người dùng | M10: Dự thảo
A11: BR-F-007 | B11: Functional BR | C11: AUTH | D11: Đổi mật khẩu | E11: Hệ thống cho phép người dùng đang đăng nhập đổi mật khẩu sau khi nhập đúng mật khẩu hiện tại. | F11: Người dùng | G11: UC-06 | H11: Must | I11: Pha 1 | J11: Đổi thành công gửi thông báo bảo mật; sai mật khẩu cũ bị từ chối. | L11: Nhu cầu người dùng | M11: Dự thảo
A12: BR-F-008 | B12: Functional BR | C12: KYC | D12: Quản lý hồ sơ cá nhân | E12: Hệ thống cho phép người dùng xem và cập nhật hồ sơ cá nhân gồm họ tên, ảnh đại diện, ngày sinh, giới thiệu ngắn và thông tin liên hệ; việc đổi email/số điện thoại phải xác thực lại bằng OTP. | F12: Người dùng | G12: UC-07 | H12: Must | I12: Pha 1 | J12: Cập nhật lưu đúng; đổi email chưa xác thực OTP không có hiệu lực. | L12: Nhu cầu người dùng | M12: Dự thảo
A13: BR-F-009 | B13: Functional BR | C13: KYC | D13: Sổ địa chỉ | E13: Hệ thống cho phép người gửi lưu, sửa, xóa các địa chỉ thường dùng (nhà, ký túc xá, cơ quan) kèm tọa độ để chọn nhanh khi tạo đơn. | F13: Người gửi | G13: UC-07, UC-12 | H13: Must | I13: Pha 1 | J13: Chọn địa chỉ đã lưu tự điền điểm lấy/giao và tọa độ. | L13: Nhu cầu người dùng | M13: Dự thảo
A14: BR-F-010 | B14: Functional BR | C14: KYC | D14: Nộp hồ sơ xác minh | E14: Hệ thống cho phép người dùng tải ảnh CCCD hai mặt và ảnh chân dung cầm CCCD, nhập thông tin CCCD và gửi hồ sơ xác minh. | F14: Người dùng | G14: UC-08 | H14: Must | I14: Pha 1 | J14: Hồ sơ gửi đi ở trạng thái Chờ duyệt; ảnh lưu mã hóa. | L14: Nhu cầu người dùng | M14: Dự thảo
A15: BR-F-011 | B15: Functional BR | C15: KYC | D15: Hàng đợi duyệt hồ sơ | E15: Hệ thống cung cấp cho Kiểm duyệt hàng đợi hồ sơ KYC với ảnh, thông tin đối chiếu và cảnh báo trùng; cho phép duyệt hoặc từ chối kèm lý do. | F15: Kiểm duyệt | G15: UC-09 | H15: Must | I15: Pha 1 | J15: Duyệt/từ chối cập nhật trạng thái và gửi thông báo cho người dùng. | L15: Nhu cầu người dùng | M15: Dự thảo
A16: BR-F-012 | B16: Functional BR | C16: KYC | D16: Đăng ký làm Người giao | E16: Hệ thống cho phép người dùng đã xác minh đăng ký vai trò Người giao: chọn phương tiện, khu vực hoạt động, khung giờ thường rảnh và xác nhận cam kết trách nhiệm. | F16: Người dùng | G16: UC-10 | H16: Must | I16: Pha 1 | J16: Đăng ký xong người dùng thấy được sàn đơn và chức năng nhận đơn. | L16: Nhu cầu người dùng | M16: Dự thảo
... A124: BR-F-120 | B124: Functional BR | C124: GAM | D124: Huy hiệu và thưởng chuyến | E124: Hệ thống trao huy hiệu và thưởng theo thành tích (số đơn trong tuần, chuỗi giao đúng hạn) theo cấu hình của Admin. | F124: Người giao | G124: UC-62 | H124: Could | I124: Pha 3 | J124: Đạt điều kiện thì tự động nhận huy hiệu/thưởng. | L124: Nhu cầu người dùng | M124: Dự thảo
A125: BR-F-121 | B125: Functional BR | C125: GAM | D125: Giới thiệu bạn bè | E125: Hệ thống cung cấp mã giới thiệu và trao thưởng 10.000đ [PRM-109] cho cả hai bên sau khi người được mời hoàn tất đơn đầu tiên. | F125: Người dùng | G125: UC-62 | H125: Could | I125: Pha 3 | J125: Thưởng chỉ ghi nhận một lần cho mỗi người được mời. | K125: PRM-109 | L125: Nhu cầu người dùng | M125: Dự thảo
A126: BR-F-122 | B126: Functional BR | C126: SYS | D126: Tìm kiếm địa chỉ và bản đồ | E126: Hệ thống cung cấp tìm kiếm địa chỉ gợi ý (geocoding), hiển thị bản đồ và tính quãng đường cho các chức năng chọn điểm và theo dõi. | F126: Người dùng | G126: UC-11, UC-12, UC-27 | H126: Must | I126: Pha 1 | J126: Gợi ý địa chỉ trả về trong ≤ 1 giây; có chế độ dự phòng khi dịch vụ lỗi. | L126: Nhu cầu người dùng | M126: Dự thảo
A127: BR-F-123 | B127: Functional BR | C127: SYS | D127: Quản lý tệp tải lên | E127: Hệ thống cung cấp dịch vụ tải và lưu trữ ảnh/tệp bằng chứng với kiểm tra loại tệp, giới hạn dung lượng và cấp liên kết truy cập có thời hạn cho dữ liệu nhạy cảm. | F127: Người dùng | G127: UC-08, UC-12, UC-25, UC-28 | H127: Must | I127: Pha 1 | J127: Tệp hợp lệ lưu thành công; liên kết nhạy cảm hết hạn đúng thời gian. | L127: Nhu cầu người dùng | M127: Dự thảo
A128: BR-F-124 | B128: Functional BR | C128: SYS | D128: Xuất dữ liệu và xóa tài khoản | E128: Hệ thống cho phép người dùng yêu cầu xuất dữ liệu cá nhân và yêu cầu xóa/ẩn danh tài khoản, Admin xử lý theo quy trình. | F128: Người dùng | G128: UC-07, UC-57 | H128: Should | I128: Pha 2 | J128: Yêu cầu tạo hồ sơ xử lý; sau xử lý dữ liệu cá nhân được xóa/ẩn danh. | L128: Nhu cầu người dùng | M128: Dự thảo
A129: BR-N-001 | B129: Non-functional BR | C129: SYS | D129: Hiệu năng – API đọc | E129: Với 500 người dùng đồng thời, 95% yêu cầu API đọc (danh sách, chi tiết) phải phản hồi trong ≤ 500 ms (không tính thời gian mạng của client). | F129: Hệ thống | G129: UC-13, UC-16 | H129: Must | I129: Pha 1 | J129: Kiểm thử tải JMeter/k6 500 VU: p95 ≤ 500 ms, lỗi < 1%. | L129: Chất lượng hệ thống | M129: Dự thảo
A130: BR-N-002 | B130: Non-functional BR | C130: SYS | D130: Hiệu năng – API ghi | E130: 95% yêu cầu API ghi thông thường (tạo đơn, gửi chào giá, đánh giá) phải phản hồi trong ≤ 1 giây. | F130: Hệ thống | G130: UC-12, UC-18, UC-47 | H130: Must | I130: Pha 1 | J130: Kiểm thử tải: p95 ≤ 1.000 ms. | L130: Chất lượng hệ thống | M130: Dự thảo
A131: BR-N-003 | B131: Non-functional BR | C131: PAY | D131: Hiệu năng – Tạo thanh toán VNPay | E131: Hệ thống phải tạo xong liên kết thanh toán VNPay và chuyển hướng người dùng trong ≤ 3 giây kể từ khi bấm thanh toán. | F131: Hệ thống | G131: UC-34, UC-35 | H131: Must | I131: Pha 1 | J131: Đo thời gian từ request đến response có URL: p95 ≤ 3 giây. | L131: Chất lượng hệ thống | M131: Dự thảo
A132: BR-N-004 | B132: Non-functional BR | C132: PAY | D132: Hiệu năng – Xử lý IPN | E132: Endpoint IPN của VNPay phải xử lý và phản hồi trong ≤ 2 giây với định dạng phản hồi mà VNPay yêu cầu; xử lý nặng phải tách bất đồng bộ. | F132: Hệ thống | G132: UC-42 | H132: Must | I132: Pha 1 | J132: Log thời gian xử lý IPN p99 ≤ 2 giây trong test với 100 IPN/phút. | L132: Chất lượng hệ thống | M132: Dự thảo
A133: BR-N-005 | B133: Non-functional BR | C133: SYS | D133: Hiệu năng – Tải trang đầu | E133: Trang đầu tiên của SPA tải xong (LCP) trong ≤ 3 giây trên mạng 4G; gói JavaScript khởi tạo ≤ 300 KB (gzip) nhờ tách mã (code splitting) và tải lười. | F133: Hệ thống | H133: Should | I133: Pha 2 | J133: Lighthouse (mobile, 4G giả lập): LCP ≤ 3 s; kích thước bundle ban đầu ≤ 300 KB gzip. | L133: Chất lượng hệ thống | M133: Dự thảo
A134: BR-N-006 | B134: Non-functional BR | C134: MKT | D134: Hiệu năng – Tìm kiếm sàn đơn | E134: Tìm kiếm/lọc/sắp xếp trên sàn đơn với 50.000 đơn phải phản hồi p95 ≤ 800 ms; có phân trang và chỉ mục phù hợp. | F134: Hệ thống | G134: UC-16 | H134: Must | I134: Pha 1 | J134: Kiểm thử với dữ liệu 50.000 đơn: p95 ≤ 800 ms. | L134: Chất lượng hệ thống | M134: Dự thảo
A135: BR-N-007 | B135: Non-functional BR | C135: TRK | D135: Hiệu năng – Độ trễ theo dõi | E135: Vị trí mới của người giao phải đến màn hình người theo dõi trong ≤ 3 giây kể từ khi gửi (trải nghiệm thời gian thực). | F135: Hệ thống | G135: UC-26, UC-27 | H135: Must | I135: Pha 1 | J135: Đo thời gian gửi–nhận trong môi trường staging: p95 ≤ 3 giây. | L135: Chất lượng hệ thống | M135: Dự thảo
A136: BR-N-008 | B136: Non-functional BR | C136: MKT | D136: Hiệu năng – Gợi ý ghép đơn | E136: Việc tính gợi ý ghép đơn–chuyến phải trả kết quả trong ≤ 2 giây với 5.000 đơn đang mở. | F136: Hệ thống | G136: UC-21 | H136: Should | I136: Pha 2 | J136: Benchmark: 5.000 đơn mở, p95 ≤ 2 giây. | L136: Chất lượng hệ thống | M136: Dự thảo
A137: BR-N-009 | B137: Non-functional BR | C137: NTF | D137: Hiệu năng – Thông báo | E137: Thông báo trong ứng dụng phải hiển thị trong ≤ 2 giây sau khi sự kiện nghiệp vụ xảy ra. | F137: Hệ thống | G137: UC-53 | H137: Should | I137: Pha 2 | J137: Đo thời gian từ sự kiện đến hiển thị: p95 ≤ 2 giây. | L137: Chất lượng hệ thống | M137: Dự thảo
A138: BR-N-010 | B138: Non-functional BR | C138: SYS | D138: Mở rộng – Số người dùng | E138: Hệ thống đáp ứng tối thiểu 500 người dùng đồng thời và 5.000 đơn/ngày; backend không giữ trạng thái phiên (stateless) để mở rộng ngang. | F138: Hệ thống | H138: Must | I138: Pha 1 | J138: Chạy 2 instance backend sau load balancer, kết quả test đạt chỉ tiêu; không dùng session cục bộ. | L138: Chất lượng hệ thống | M138: Dự thảo
A139: BR-N-011 | B139: Non-functional BR | C139: TRK | D139: Mở rộng – Kết nối thời gian thực | E139: Kênh WebSocket hỗ trợ tối thiểu 1.000 kết nối đồng thời trên một cụm triển khai. | F139: Hệ thống | G139: UC-24, UC-27 | H139: Should | I139: Pha 2 | J139: Kiểm thử 1.000 kết nối WebSocket, tỷ lệ rớt < 1%. | L139: Chất lượng hệ thống | M139: Dự thảo
A140: BR-N-012 | B140: Non-functional BR | C140: SYS | D140: Sẵn sàng – Thời gian hoạt động | E140: Độ khả dụng ≥ 99,5% mỗi tháng trong giai đoạn pilot (không tính bảo trì đã thông báo trước ≥ 24 giờ). | F140: Hệ thống | H140: Should | I140: Pha 2 | J140: Giám sát uptime hằng tháng ≥ 99,5%. | L140: Chất lượng hệ thống | M140: Dự thảo
A141: BR-N-013 | B141: Non-functional BR | C141: SYS | D141: Sẵn sàng – Sao lưu và khôi phục | E141: Sao lưu SQL Server và MongoDB hằng ngày; RPO ≤ 24 giờ, RTO ≤ 4 giờ; kiểm thử khôi phục tối thiểu 1 lần/tháng. | F141: Hệ thống | H141: Should | I141: Pha 2 | J141: Biên bản diễn tập khôi phục thành công; có script backup tự động. | L141: Chất lượng hệ thống | M141: Dự thảo
A142: BR-N-014 | B142: Non-functional BR | C142: SYS | D142: Tin cậy – Chịu lỗi dịch vụ ngoài | E142: Mọi lời gọi dịch vụ ngoài (VNPay, định tuyến, email/SMS) phải có timeout, thử lại có giới hạn và ngắt mạch (circuit breaker); lỗi dịch vụ ngoài không được làm sập hệ thống. | F142: Hệ thống | G142: UC-34, UC-11, UC-53 | H142: Must | I142: Pha 1 | J142: Giả lập dịch vụ ngoài lỗi: hệ thống trả lỗi có kiểm soát, các chức năng khác vẫn hoạt động. | L142: Chất lượng hệ thống | M142: Dự thảo
A143: BR-N-015 | B143: Non-functional BR | C143: SYS | D143: Tin cậy – Tác vụ định kỳ | E143: Tác vụ nền (hết hạn đơn, tự giải ngân, đối soát) chỉ chạy đúng một lần khi có nhiều instance, có khả năng chạy lại an toàn (idempotent) và ghi nhật ký kết quả. | F143: Hệ thống | G143: UC-63, UC-43 | H143: Must | I143: Pha 1 | J143: Chạy 2 instance: mỗi job thực thi 1 lần/chu kỳ; chạy lại không tạo dữ liệu trùng. | L143: Chất lượng hệ thống | M143: Dự thảo
A144: BR-N-016 | B144: Non-functional BR | C144: AUTH | D144: Bảo mật – Băm mật khẩu | E144: Mật khẩu chỉ được lưu dưới dạng băm BCrypt (cost ≥ 10); không lưu và không ghi log mật khẩu bản rõ. | F144: Hệ thống | G144: UC-01, UC-06 | H144: Must | I144: Pha 1 | J144: Rà soát CSDL và log: không có mật khẩu rõ; cost factor ≥ 10. | L144: Chất lượng hệ thống | M144: Dự thảo
A145: BR-N-017 | B145: Non-functional BR | C145: SYS | D145: Bảo mật – Mã hóa đường truyền | E145: Toàn bộ truy cập qua HTTPS (TLS ≥ 1.2) và bật HSTS; WebSocket dùng WSS. | F145: Hệ thống | H145: Must | I145: Pha 1 | J145: Quét SSL Labs/testssl: không cho phép giao thức < TLS 1.2. | L145: Chất lượng hệ thống | M145: Dự thảo
A146: BR-N-018 | B146: Non-functional BR | C146: KYC | D146: Bảo mật – Mã hóa dữ liệu nhạy cảm | E146: Ảnh CCCD, ảnh chân dung và số tài khoản ngân hàng được mã hóa khi lưu (AES-256-GCM); khóa mã hóa quản lý ngoài mã nguồn và có quy trình xoay khóa. | F146: Hệ thống | G146: UC-08, UC-39 | H146: Must | I146: Pha 1 | J146: Kiểm tra dữ liệu thô trong kho lưu trữ không đọc được; khóa lấy từ biến môi trường/secret store. | L146: Chất lượng hệ thống | M146: Dự thảo
A147: BR-N-019 | B147: Non-functional BR | C147: SYS | D147: Bảo mật – OWASP Top 10 | E147: Hệ thống phải được kiểm thử và phòng chống các rủi ro OWASP Top 10 (injection, XSS, CSRF, broken access control, SSRF…); nghiệm thu không còn lỗ hổng mức Cao/Nghiêm trọng. | F147: Hệ thống | H147: Must | I147: Pha 1 | J147: Báo cáo kiểm thử bảo mật (ZAP/checklist OWASP ASVS cơ bản): 0 lỗ hổng Cao/Nghiêm trọng. | L147: Chất lượng hệ thống | M147: Dự thảo
A148: BR-N-020 | B148: Non-functional BR | C148: SYS | D148: Bảo mật – Kiểm soát truy cập đối tượng | E148: Người dùng chỉ truy cập được đơn, ví, chat và hồ sơ thuộc quyền của mình; mọi endpoint phải kiểm tra quyền sở hữu phía máy chủ (chống BOLA/IDOR). | F148: Hệ thống | G148: UC-13, UC-38 | H148: Must | I148: Pha 1 | J148: Kiểm thử thay đổi ID trong URL: trả 403/404 cho dữ liệu không thuộc quyền. | L148: Chất lượng hệ thống | M148: Dự thảo
...

Sheet 04_UC
A1: Danh mục Use Case
A2: 63 UC • luồng chính và ngoại lệ • BR liên quan tự động tổng hợp từ sheet 03 • giờ ước lượng, người phụ trách và sprint (nguồn cho sheet 13 và 14)
A4: Mã UC | B4: Tên Use Case | C4: Phân hệ | D4: Tác nhân chính | E4: Tác nhân phụ | F4: Ưu tiên | G4: Pha | H4: Tiền điều kiện | I4: Hậu điều kiện | J4: Luồng chính | K4: Luồng thay thế / ngoại lệ | L4: BR liên quan | M4: Màn hình | N4: Số API | O4: Dev | P4: Sprint hoàn thành | Q4: Tổng giờ | R4: Trạng thái | S4: Ngày bắt đầu | T4: Hạn chót
A5: UC-01 | B5: Đăng ký tài khoản | C5: AUTH | D5: Khách | E5: Dịch vụ Email/SMS | F5: Must | G5: Pha 1 | H5: Email/SĐT chưa có tài khoản. | I5: Tài khoản trạng thái Chờ xác thực được tạo; OTP đã gửi. | J5: 1. Khách mở trang đăng ký 2. Nhập họ tên, email, SĐT, mật khẩu, xác nhận đủ 18 tuổi 3. Đồng ý Điều khoản và Chính sách dữ liệu 4. Hệ thống kiểm tra định dạng và trùng lặp 5. Hệ thống tạo tài khoản (băm mật khẩu), gán vai trò Người gửi 6. Hệ thống gửi OTP và chuyển sang UC-02 | K5: • A1 Email/SĐT đã tồn tại: báo lỗi, gợi ý đăng nhập/quên mật khẩu • A2 Mật khẩu không đạt: hiển thị yêu cầu • A3 SĐT/CCCD thuộc danh sách đen: từ chối | L5: BR-F-001, BR-N-016, BR-N-030, BR-R-001, BR-R-002, BR-C-011, BR-C-022, BR-G-002 | M5: SCR-03 | N5: =COUNTIF('10_API'!$G:$G,A5) -> 1 | O5: =VLOOKUP(A5, '15_Chia task(UC)'!$D$7:$G$69, 3, FALSE) -> Lư Hữu Luân | P5: =VLOOKUP(A5, '15_Chia task(UC)'!$D$7:$G$69, 4, FALSE) -> Sprint 1 | Q5: =IF(O5="Trần Công Thuận", 6, 8) -> 8 | R5: Dự thảo | S5: =VLOOKUP(A5, '15_Chia task(UC)'!$D$7:$I$69, 5, FALSE) -> 46305 | T5: =VLOOKUP(A5, '15_Chia task(UC)'!$D$7:$I$69, 6, FALSE) -> 46307
A6: UC-02 | B6: Xác thực OTP email/SĐT | C6: AUTH | D6: Người dùng | E6: Dịch vụ Email/SMS | F6: Must | G6: Pha 1 | H6: Có tài khoản Chờ xác thực hoặc yêu cầu xác thực mới. | I6: Tài khoản/kênh liên lạc được xác thực. | J6: 1. Người dùng nhập OTP 2. Hệ thống kiểm tra mã, thời hạn, số lần thử 3. Hệ thống đánh dấu đã xác thực, kích hoạt tài khoản 4. Chuyển người dùng vào ứng dụng | K6: • A1 OTP sai: tăng đếm, báo lỗi • A2 OTP hết hạn: cho gửi lại sau thời gian chờ • A3 Quá số lần sai: vô hiệu OTP | L6: BR-F-002, BR-F-102, BR-R-003, BR-R-007 | M6: SCR-04 | N6: =COUNTIF('10_API'!$G:$G,A6) -> 2 | O6: =VLOOKUP(A6, '15_Chia task(UC)'!$D$7:$G$69, 3, FALSE) -> Lư Hữu Luân | P6: =VLOOKUP(A6, '15_Chia task(UC)'!$D$7:$G$69, 4, FALSE) -> Sprint 1 | Q6: =IF(O6="Trần Công Thuận", 6, 8) -> 8 | R6: Dự thảo | S6: =VLOOKUP(A6, '15_Chia task(UC)'!$D$7:$I$69, 5, FALSE) -> 46305 | T6: =VLOOKUP(A6, '15_Chia task(UC)'!$D$7:$I$69, 6, FALSE) -> 46307
A7: UC-03 | B7: Đăng nhập | C7: AUTH | D7: Người dùng | F7: Must | G7: Pha 1 | H7: Tài khoản tồn tại, không bị khóa. | I7: Phiên đăng nhập được tạo, trả Access/Refresh Token. | J7: 1. Người dùng nhập tài khoản và mật khẩu 2. Hệ thống xác thực thông tin 3. Hệ thống kiểm tra trạng thái, số thiết bị 4. Hệ thống cấp token và trả thông tin vai trò 5. Giao diện điều hướng theo vai trò | K7: • A1 Sai thông tin: tăng đếm sai • A2 Quá số lần sai: khóa tạm • A3 Tài khoản bị khóa: thông báo lý do chung • A4 Đăng nhập Google (Could) | L7: BR-F-003, BR-F-004, BR-N-024, BR-R-004, BR-R-005, BR-R-006, BR-C-005 | M7: SCR-05 | N7: =COUNTIF('10_API'!$G:$G,A7) -> 3 | O7: =VLOOKUP(A7, '15_Chia task(UC)'!$D$7:$G$69, 3, FALSE) -> Lư Hữu Luân | P7: =VLOOKUP(A7, '15_Chia task(UC)'!$D$7:$G$69, 4, FALSE) -> Sprint 2 | Q7: =IF(O7="Trần Công Thuận", 6, 8) -> 8 | R7: Dự thảo | S7: =VLOOKUP(A7, '15_Chia task(UC)'!$D$7:$I$69, 5, FALSE) -> 46308 | T7: =VLOOKUP(A7, '15_Chia task(UC)'!$D$7:$I$69, 6, FALSE) -> 46314
A8: UC-04 | B8: Đăng xuất và quản lý phiên/thiết bị | C8: AUTH | D8: Người dùng | F8: Must | G8: Pha 1 | H8: Đã đăng nhập. | I8: Phiên bị thu hồi. | J8: 1. Người dùng chọn Đăng xuất hoặc mở danh sách thiết bị 2. Hệ thống hiển thị phiên đang hoạt động 3. Người dùng thu hồi phiên 4. Hệ thống vô hiệu refresh token của phiên | K8: • A1 Thu hồi phiên hiện tại: chuyển về trang đăng nhập | L8: BR-F-005, BR-R-005, BR-R-006 | M8: SCR-12 | N8: =COUNTIF('10_API'!$G:$G,A8) -> 3 | O8: =VLOOKUP(A8, '15_Chia task(UC)'!$D$7:$G$69, 3, FALSE) -> Lư Hữu Luân | P8: =VLOOKUP(A8, '15_Chia task(UC)'!$D$7:$G$69, 4, FALSE) -> Sprint 2 | Q8: =IF(O8="Trần Công Thuận", 6, 8) -> 8 | R8: Dự thảo | S8: =VLOOKUP(A8, '15_Chia task(UC)'!$D$7:$I$69, 5, FALSE) -> 46308 | T8: =VLOOKUP(A8, '15_Chia task(UC)'!$D$7:$I$69, 6, FALSE) -> 46314
A9: UC-05 | B9: Quên và đặt lại mật khẩu | C9: AUTH | D9: Người dùng | E9: Dịch vụ Email/SMS | F9: Must | G9: Pha 1 | H9: Tài khoản tồn tại. | I9: Mật khẩu mới có hiệu lực; mọi phiên cũ bị thu hồi. | J9: 1. Người dùng nhập email/SĐT 2. Hệ thống gửi OTP 3. Người dùng nhập OTP và mật khẩu mới 4. Hệ thống cập nhật mật khẩu, thu hồi phiên 5. Thông báo bảo mật | K9: • A1 Email/SĐT không tồn tại: vẫn báo đã gửi (chống dò tài khoản) • A2 OTP sai/hết hạn | L9: BR-F-006, BR-N-024, BR-R-002, BR-R-003 | M9: SCR-06, SCR-07 | N9: =COUNTIF('10_API'!$G:$G,A9) -> 2 | O9: =VLOOKUP(A9, '15_Chia task(UC)'!$D$7:$G$69, 3, FALSE) -> Lư Hữu Luân | P9: =VLOOKUP(A9, '15_Chia task(UC)'!$D$7:$G$69, 4, FALSE) -> Sprint 5 | Q9: =IF(O9="Trần Công Thuận", 6, 8) -> 8 | R9: Dự thảo | S9: =VLOOKUP(A9, '15_Chia task(UC)'!$D$7:$I$69, 5, FALSE) -> 46329 | T9: =VLOOKUP(A9, '15_Chia task(UC)'!$D$7:$I$69, 6, FALSE) -> 46339
A10: UC-06 | B10: Đổi mật khẩu | C10: AUTH | D10: Người dùng | F10: Must | G10: Pha 1 | H10: Đã đăng nhập. | I10: Mật khẩu được đổi. | J10: 1. Người dùng nhập mật khẩu hiện tại và mật khẩu mới 2. Hệ thống kiểm tra 3. Hệ thống cập nhật và gửi thông báo bảo mật | K10: • A1 Sai mật khẩu hiện tại: từ chối • A2 Mật khẩu mới không đạt quy tắc | L10: BR-F-007, BR-N-016, BR-R-002 | M10: SCR-12 | N10: =COUNTIF('10_API'!$G:$G,A10) -> 1 | O10: =VLOOKUP(A10, '15_Chia task(UC)'!$D$7:$G$69, 3, FALSE) -> Lư Hữu Luân | P10: =VLOOKUP(A10, '15_Chia task(UC)'!$D$7:$G$69, 4, FALSE) -> Sprint 3 | Q10: =IF(O10="Trần Công Thuận", 6, 8) -> 8 | R10: Dự thảo | S10: =VLOOKUP(A10, '15_Chia task(UC)'!$D$7:$I$69, 5, FALSE) -> 46315 | T10: =VLOOKUP(A10, '15_Chia task(UC)'!$D$7:$I$69, 6, FALSE) -> 46321
A11: UC-07 | B11: Quản lý hồ sơ cá nhân và sổ địa chỉ | C11: KYC | D11: Người dùng | F11: Must | G11: Pha 1 | H11: Đã đăng nhập. | I11: Hồ sơ/địa chỉ được cập nhật. | J11: 1. Người dùng mở trang hồ sơ 2. Chỉnh sửa thông tin hoặc thêm/sửa/xóa địa chỉ trên bản đồ 3. Hệ thống kiểm tra và lưu 4. Nếu đổi email/SĐT, yêu cầu OTP xác thực lại | K11: • A1 Email thuộc miền FPT: cấp huy hiệu Cộng đồng FPT • A2 Yêu cầu xuất dữ liệu/xóa tài khoản: tạo hồ sơ xử lý | L11: BR-F-004, BR-F-008, BR-F-009, BR-F-124, BR-N-040, BR-R-014 | M11: SCR-10, SCR-11 | N11: =COUNTIF('10_API'!$G:$G,A11) -> 9 | O11: =VLOOKUP(A11, '15_Chia task(UC)'!$D$7:$G$69, 3, FALSE) -> Lư Hữu Luân | P11: =VLOOKUP(A11, '15_Chia task(UC)'!$D$7:$G$69, 4, FALSE) -> Sprint 4 | Q11: =IF(O11="Trần Công Thuận", 6, 8) -> 8 | R11: Dự thảo | S11: =VLOOKUP(A11, '15_Chia task(UC)'!$D$7:$I$69, 5, FALSE) -> 46322 | T11: =VLOOKUP(A11, '15_Chia task(UC)'!$D$7:$I$69, 6, FALSE) -> 46328
A12: UC-08 | B12: Gửi hồ sơ xác minh danh tính (KYC) | C12: KYC | D12: Người dùng | F12: Must | G12: Pha 1 | H12: Đã xác thực OTP. | I12: Hồ sơ KYC ở trạng thái Chờ duyệt. | J12: 1. Người dùng mở màn hình xác minh 2. Nhập thông tin CCCD 3. Tải ảnh CCCD hai mặt và ảnh chân dung cầm CCCD 4. Hệ thống kiểm tra tệp, trùng CCCD, độ tuổi 5. Hệ thống mã hóa lưu và tạo hồ sơ chờ duyệt | K12: • A1 CCCD đã gắn tài khoản khác: từ chối, đánh dấu rà soát • A2 Dưới 18 tuổi: từ chối • A3 Vượt số lần nộp lại cho phép | L12: BR-F-010, BR-F-123, BR-N-018, BR-N-023, BR-R-010, BR-R-011, BR-C-011, BR-G-002 | M12: SCR-13 | N12: =COUNTIF('10_API'!$G:$G,A12) -> 2 | O12: =VLOOKUP(A12, '15_Chia task(UC)'!$D$7:$G$69, 3, FALSE) -> Lư Hữu Luân | P12: =VLOOKUP(A12, '15_Chia task(UC)'!$D$7:$G$69, 4, FALSE) -> Sprint 4 | Q12: =IF(O12="Trần Công Thuận", 6, 8) -> 8 | R12: Dự thảo | S12: =VLOOKUP(A12, '15_Chia task(UC)'!$D$7:$I$69, 5, FALSE) -> 46322 | T12: =VLOOKUP(A12, '15_Chia task(UC)'!$D$7:$I$69, 6, FALSE) -> 46328
A13: UC-09 | B13: Duyệt hồ sơ xác minh | C13: KYC | D13: Kiểm duyệt | E13: Người dùng | F13: Must | G13: Pha 1 | H13: Có hồ sơ Chờ duyệt. | I13: Hồ sơ Đã duyệt hoặc Từ chối kèm lý do. | J13: 1. Kiểm duyệt mở hàng đợi KYC 2. Xem ảnh và thông tin đối chiếu 3. Chọn Duyệt hoặc Từ chối (chọn lý do) 4. Hệ thống cập nhật trạng thái, ghi audit 5. Hệ thống thông báo người dùng | K13: • A1 Nghi ngờ gian lận: đánh dấu và chuyển Admin • A2 Quá SLA: hệ thống cảnh báo | L13: BR-F-011, BR-R-011, BR-R-012, BR-R-082, BR-R-084 | M13: SCR-50 | N13: =COUNTIF('10_API'!$G:$G,A13) -> 4 | O13: =VLOOKUP(A13, '15_Chia task(UC)'!$D$7:$G$69, 3, FALSE) -> Trần Công Thuận | P13: =VLOOKUP(A13, '15_Chia task(UC)'!$D$7:$G$69, 4, FALSE) -> Sprint 1 | Q13: =IF(O13="Trần Công Thuận", 6, 8) -> 6 | R13: Dự thảo | S13: =VLOOKUP(A13, '15_Chia task(UC)'!$D$7:$I$69, 5, FALSE) -> 46305 | T13: =VLOOKUP(A13, '15_Chia task(UC)'!$D$7:$I$69, 6, FALSE) -> 46307
A14: UC-10 | B14: Đăng ký làm Người giao | C14: KYC | D14: Người dùng | F14: Must | G14: Pha 1 | H14: KYC đã duyệt. | I14: Tài khoản có vai trò Người giao. | J14: 1. Người dùng chọn Trở thành Người giao 2. Chọn phương tiện, khu vực, khung giờ 3. Đọc và xác nhận cam kết trách nhiệm 4. Hệ thống gán vai trò Người giao, hạng Tân binh 5. Giao diện cho phép chuyển chế độ | K14: • A1 KYC chưa duyệt: hướng dẫn đi UC-08 | L14: BR-F-012, BR-F-013, BR-R-009, BR-C-022, BR-G-002 | M14: SCR-14 | N14: =COUNTIF('10_API'!$G:$G,A14) -> 1 | O14: =VLOOKUP(A14, '15_Chia task(UC)'!$D$7:$G$69, 3, FALSE) -> Lư Hữu Luân | P14: =VLOOKUP(A14, '15_Chia task(UC)'!$D$7:$G$69, 4, FALSE) -> Sprint 3 | Q14: =IF(O14="Trần Công Thuận", 6, 8) -> 8 | R14: Dự thảo | S14: =VLOOKUP(A14, '15_Chia task(UC)'!$D$7:$I$69, 5, FALSE) -> 46315 | T14: =VLOOKUP(A14, '15_Chia task(UC)'!$D$7:$I$69, 6, FALSE) -> 46321
A15: UC-11 | B15: Ước tính giá và phí | C15: ORD | D15: Người gửi | E15: Dịch vụ Bản đồ | F15: Must | G15: Pha 1 | H15: Có điểm lấy, điểm giao, thông tin hàng. | I15: Hiển thị giá gợi ý và cấu thành phí. | J15: 1. Người gửi nhập điểm lấy và điểm giao 2. Hệ thống tính quãng đường 3. Người gửi nhập khối lượng, kích thước, mức khẩn cấp, bảo hiểm 4. Hệ thống tính giá gợi ý theo công thức 5. Hiển thị bảng cấu thành phí | K15: • A1 Dịch vụ định tuyến lỗi: dùng khoảng cách dự phòng và đánh dấu ước tính • A2 Vượt giới hạn tuyến/hàng: thông báo | L15: BR-F-014, BR-F-015, BR-F-018, BR-F-086, BR-F-122, BR-N-014, BR-R-017, BR-R-063, BR-R-065, BR-R-066, BR-R-068, BR-C-021, BR-G-001 | M15: SCR-01, SCR-02, SCR-17 | N15: =COUNTIF('10_API'!$G:$G,A15) -> 2 | O15: =VLOOKUP(A15, '15_Chia task(UC)'!$D$7:$G$69, 3, FALSE) -> Nguyễn Thành Huy | P15: =VLOOKUP(A15, '15_Chia task(UC)'!$D$7:$G$69, 4, FALSE) -> Sprint 1 | Q15: =IF(O15="Trần Công Thuận", 6, 8) -> 8 | R15: Dự thảo | S15: =VLOOKUP(A15, '15_Chia task(UC)'!$D$7:$I$69, 5, FALSE) -> 46305 | T15: =VLOOKUP(A15, '15_Chia task(UC)'!$D$7:$I$69, 6, FALSE) -> 46307
A16: UC-12 | B16: Tạo đơn giao hàng | C16: ORD | D16: Người gửi | E16: Dịch vụ Bản đồ | F16: Must | G16: Pha 1 | H16: Đã xác thực OTP, không bị khóa, chưa vượt số đơn mở. | I16: Đơn được tạo ở trạng thái Chờ kiểm duyệt hoặc Đang mở. | J16: 1. Người gửi chọn Tạo đơn 2. Chọn điểm lấy/giao 3. Khai báo hàng, tải ảnh, nhập người nhận 4. Chọn tùy chọn giao và cách tìm người giao 5. Xem giá và xác nhận đăng 6. Hệ thống kiểm tra giới hạn, sinh mã vận đơn 7. Hệ thống chạy kiểm duyệt tự động (UC-54) 8. Hệ thống đưa đơn lên sàn hoặc chuyển Kiểm duyệt | K16: • A1 Vượt giới hạn hàng: chặn và nêu lý do • A2 Lưu nháp: đơn chưa lên sàn • A3 Đơn vi phạm từ khóa: chờ kiểm duyệt | L16: BR-F-009, BR-F-015, BR-F-016, BR-F-017, BR-F-018, BR-F-019, BR-F-020, BR-F-025, BR-F-122, BR-F-123, BR-N-002, BR-N-023, BR-N-027, BR-N-030, BR-R-007, BR-R-015, BR-R-016, BR-R-017, BR-R-018, BR-R-019, BR-R-020, BR-R-023, BR-R-026, BR-R-080, BR-C-012, BR-C-020, BR-G-001 | M16: SCR-17 | N16: =COUNTIF('10_API'!$G:$G,A16) -> 6 | O16: =VLOOKUP(A16, '15_Chia task(UC)'!$D$7:$G$69, 3, FALSE) -> Nguyễn Thành Huy | P16: =VLOOKUP(A16, '15_Chia task(UC)'!$D$7:$G$69, 4, FALSE) -> Sprint 1 | Q16: =IF(O16="Trần Công Thuận", 6, 8) -> 8 | R16: Dự thảo | S16: =VLOOKUP(A16, '15_Chia task(UC)'!$D$7:$I$69, 5, FALSE) -> 46305 | T16: =VLOOKUP(A16, '15_Chia task(UC)'!$D$7:$I$69, 6, FALSE) -> 46307
A17: UC-13 | B17: Xem danh sách và chi tiết đơn của tôi | C17: ORD | D17: Người dùng | F17: Must | G17: Pha 1 | H17: Đã đăng nhập. | I17: Hiển thị dữ liệu đơn thuộc quyền. | J17: 1. Người dùng mở Đơn của tôi 2. Lọc theo trạng thái/thời gian, tìm theo mã 3. Chọn một đơn 4. Hệ thống hiển thị chi tiết, người giao, giá, bằng chứng, timeline | K17: • A1 Truy cập đơn không thuộc quyền: 403/404 | L17: BR-F-020, BR-F-021, BR-F-022, BR-F-025, BR-N-001, BR-N-020, BR-N-031, BR-R-023, BR-R-045 | M17: SCR-16, SCR-18, SCR-19, SCR-31 | N17: =COUNTIF('10_API'!$G:$G,A17) -> 3 | O17: =VLOOKUP(A17, '15_Chia task(UC)'!$D$7:$G$69, 3, FALSE) -> Nguyễn Thành Huy | P17: =VLOOKUP(A17, '15_Chia task(UC)'!$D$7:$G$69, 4, FALSE) -> Sprint 2 | Q17: =IF(O17="Trần Công Thuận", 6, 8) -> 8 | R17: Dự thảo | S17: =VLOOKUP(A17, '15_Chia task(UC)'!$D$7:$I$69, 5, FALSE) -> 46308 | T17: =VLOOKUP(A17, '15_Chia task(UC)'!$D$7:$I$69, 6, FALSE) -> 46314
A18: UC-14 | B18: Sửa đơn | C18: ORD | D18: Người gửi | F18: Must | G18: Pha 1 | H18: Đơn ở Chờ kiểm duyệt/Đang mở, chưa có chào giá được chấp nhận. | I18: Đơn được cập nhật; chào giá bị ảnh hưởng được hủy. | J18: 1. Người gửi chọn Sửa đơn 2. Chỉnh thông tin 3. Hệ thống cảnh báo ảnh hưởng đến chào giá 4. Người gửi xác nhận 5. Hệ thống lưu, kiểm duyệt lại nếu cần, thông báo người đã chào giá | K18: • A1 Đơn đã có người giao: không cho sửa | L18: BR-F-023, BR-R-019, BR-R-021 | M18: SCR-20 | N18: =COUNTIF('10_API'!$G:$G,A18) -> 1 | O18: =VLOOKUP(A18, '15_Chia task(UC)'!$D$7:$G$69, 3, FALSE) -> Nguyễn Thành Huy | P18: =VLOOKUP(A18, '15_Chia task(UC)'!$D$7:$G$69, 4, FALSE) -> Sprint 2 | Q18: =IF(O18="Trần Công Thuận", 6, 8) -> 8 | R18: Dự thảo | S18: =VLOOKUP(A18, '15_Chia task(UC)'!$D$7:$I$69, 5, FALSE) -> 46308 | T18: =VLOOKUP(A18, '15_Chia task(UC)'!$D$7:$I$69, 6, FALSE) -> 46314
A19: UC-15 | B19: Hủy đơn | C19: ORD | D19: Người gửi | E19: Người giao | F19: Must | G19: Pha 1 | H19: Đơn chưa ở trạng thái Đã lấy hàng. | I19: Đơn Đã hủy; tiền xử lý theo quy tắc hủy. | J19: 1. Người dùng chọn Hủy đơn 2. Hệ thống hiển thị phí hủy và số tiền hoàn 3. Người dùng nhập lý do và xác nhận 4. Hệ thống cập nhật trạng thái, thực hiện hoàn tiền (UC-37), thông báo bên còn lại | K19: • A1 Người giao hủy: trừ điểm uy tín, đơn quay về sàn • A2 Đơn đã lấy hàng: hướng dẫn UC-29/UC-30 | L19: BR-F-024, BR-R-022, BR-R-075 | N19: =COUNTIF('10_API'!$G:$G,A19) -> 1 | O19: =VLOOKUP(A19, '15_Chia task(UC)'!$D$7:$G$69, 3, FALSE) -> Nguyễn Thành Huy | P19: =VLOOKUP(A19, '15_Chia task(UC)'!$D$7:$G$69, 4, FALSE) -> Sprint 5 | Q19: =IF(O19="Trần Công Thuận", 6, 8) -> 8 | R19: Dự thảo | S19: =VLOOKUP(A19, '15_Chia task(UC)'!$D$7:$I$69, 5, FALSE) -> 46329 | T19: =VLOOKUP(A19, '15_Chia task(UC)'!$D$7:$I$69, 6, FALSE) -> 46339
A20: UC-16 | B20: Duyệt và tìm kiếm sàn đơn | C20: MKT | D20: Người giao | F20: Must | G20: Pha 1 | H20: Người giao đã được duyệt. | I20: Hiển thị danh sách đơn đủ điều kiện. | J20: 1. Người giao mở Sàn đơn 2. Hệ thống hiển thị đơn Đang mở (ẩn thông tin nhạy cảm) 3. Người giao lọc/sắp xếp hoặc xem bản đồ 4. Chọn một đơn để xem chi tiết | K20: • A1 Không có đơn phù hợp: gợi ý đăng ký thông báo khu vực | L20: BR-F-026, BR-F-027, BR-F-028, BR-F-035, BR-N-001, BR-N-006, BR-N-031, BR-R-024, BR-R-027, BR-G-003 | M20: SCR-28, SCR-29 | N20: =COUNTIF('10_API'!$G:$G,A20) -> 4 | O20: =VLOOKUP(A20, '15_Chia task(UC)'!$D$7:$G$69, 3, FALSE) -> Võ Quốc An | P20: =VLOOKUP(A20, '15_Chia task(UC)'!$D$7:$G$69, 4, FALSE) -> Sprint 1 | Q20: =IF(O20="Trần Công Thuận", 6, 8) -> 8 | R20: Dự thảo | S20: =VLOOKUP(A20, '15_Chia task(UC)'!$D$7:$I$69, 5, FALSE) -> 46305 | T20: =VLOOKUP(A20, '15_Chia task(UC)'!$D$7:$I$69, 6, FALSE) -> 46307
A21: UC-17 | B21: Nhận đơn (giá niêm yết) | C21: MKT | D21: Người giao | E21: Người gửi | F21: Must | G21: Pha 1 | H21: Đơn Đang mở; người giao đủ điều kiện hạng/hạn mức. | I21: Đơn chuyển Chờ ký quỹ, gắn người giao. | J21: 1. Người giao chọn Nhận đơn 2. Hệ thống kiểm tra KYC, hạn mức, hạng, giá trị cao 3. Hệ thống khóa đơn cho người giao (xử lý tranh chấp đồng thời) 4. Hệ thống chuyển trạng thái, thông báo người gửi để ký quỹ | K21: • A1 Người khác đã nhận: báo đơn không còn khả dụng • A2 Vượt hạn mức: từ chối kèm lý do | L21: BR-F-029, BR-N-027, BR-R-008, BR-R-009, BR-R-024, BR-R-025, BR-R-028, BR-G-003 | M21: SCR-30 | N21: =COUNTIF('10_API'!$G:$G,A21) -> 1 | O21: =VLOOKUP(A21, '15_Chia task(UC)'!$D$7:$G$69, 3, FALSE) -> Võ Quốc An | P21: =VLOOKUP(A21, '15_Chia task(UC)'!$D$7:$G$69, 4, FALSE) -> Sprint 1 | Q21: =IF(O21="Trần Công Thuận", 6, 8) -> 8 | R21: Dự thảo | S21: =VLOOKUP(A21, '15_Chia task(UC)'!$D$7:$I$69, 5, FALSE) -> 46305 | T21: =VLOOKUP(A21, '15_Chia task(UC)'!$D$7:$I$69, 6, FALSE) -> 46307
A22: UC-18 | B22: Gửi chào giá | C22: MKT | D22: Người giao | E22: Người gửi | F22: Must | G22: Pha 1 | H22: Đơn Đang mở; người giao đủ điều kiện. | I22: Chào giá ở trạng thái Chờ phản hồi. | J22: 1. Người giao nhập giá chào, lời nhắn, thời gian lấy dự kiến 2. Hệ thống kiểm tra biên giá 3. Hệ thống lưu chào giá (thay thế chào giá cũ nếu có) 4. Thông báo người gửi | K22: • A1 Giá ngoài biên: từ chối | L22: BR-F-030, BR-N-002, BR-R-008, BR-R-009, BR-R-028, BR-R-029, BR-R-030, BR-G-003 | M22: SCR-30 | N22: =COUNTIF('10_API'!$G:$G,A22) -> 3 | O22: =VLOOKUP(A22, '15_Chia task(UC)'!$D$7:$G$69, 3, FALSE) -> Võ Quốc An | P22: =VLOOKUP(A22, '15_Chia task(UC)'!$D$7:$G$69, 4, FALSE) -> Sprint 2 | Q22: =IF(O22="Trần Công Thuận", 6, 8) -> 8 | R22: Dự thảo | S22: =VLOOKUP(A22, '15_Chia task(UC)'!$D$7:$I$69, 5, FALSE) -> 46308 | T22: =VLOOKUP(A22, '15_Chia task(UC)'!$D$7:$I$69, 6, FALSE) -> 46314
A23: UC-19 | B23: Xử lý chào giá (chấp nhận, từ chối, phản giá) | C23: MKT | D23: Người gửi | E23: Người giao | F23: Must | G23: Pha 1 | H23: Đơn có chào giá hiệu lực. | I23: Chào giá được chấp nhận/từ chối/phản giá. | J23: 1. Người gửi mở danh sách chào giá 2. So sánh giá, hạng, điểm uy tín 3. Chọn chấp nhận, từ chối hoặc phản giá 4. Nếu chấp nhận: chốt người giao, từ chối các chào giá khác, đơn sang Chờ ký quỹ 5. Thông báo các bên | K23: • A1 Phản giá: người giao có thể chấp nhận hoặc phản giá lại theo giới hạn vòng • A2 Chào giá hết hạn: tự động Hết hạn | L23: BR-F-031, BR-F-032, BR-F-086, BR-F-094, BR-R-025, BR-R-029, BR-R-031, BR-R-032 | M23: SCR-21 | N23: =COUNTIF('10_API'!$G:$G,A23) -> 4 | O23: =VLOOKUP(A23, '15_Chia task(UC)'!$D$7:$G$69, 3, FALSE) -> Võ Quốc An | P23: =VLOOKUP(A23, '15_Chia task(UC)'!$D$7:$G$69, 4, FALSE) -> Sprint 2 | Q23: =IF(O23="Trần Công Thuận", 6, 8) -> 8 | R23: Dự thảo | S23: =VLOOKUP(A23, '15_Chia task(UC)'!$D$7:$I$69, 5, FALSE) -> 46308 | T23: =VLOOKUP(A23, '15_Chia task(UC)'!$D$7:$I$69, 6, FALSE) -> 46314
A24: UC-20 | B24: Mời trực tiếp người giao | C24: MKT | D24: Người gửi | E24: Người giao | F24: Could | G24: Pha 3 | H24: Người gửi có đơn Đang mở hoặc đang tạo. | I24: Lời mời được gửi. | J24: 1. Người gửi chọn người giao yêu thích hoặc tìm theo mã 2. Gửi lời mời kèm đơn 3. Người giao nhận thông báo, chấp nhận hoặc từ chối | K24: • A1 Lời mời hết hạn: đơn lên sàn công khai | L24: BR-F-019, BR-F-033 | N24: =COUNTIF('10_API'!$G:$G,A24) -> 2 | O24: =VLOOKUP(A24, '15_Chia task(UC)'!$D$7:$G$69, 3, FALSE) -> Võ Quốc An | P24: =VLOOKUP(A24, '15_Chia task(UC)'!$D$7:$G$69, 4, FALSE) -> Sprint 4 | Q24: =IF(O24="Trần Công Thuận", 6, 8) -> 8 | R24: Dự thảo | S24: =VLOOKUP(A24, '15_Chia task(UC)'!$D$7:$I$69, 5, FALSE) -> 46322 | T24: =VLOOKUP(A24, '15_Chia task(UC)'!$D$7:$I$69, 6, FALSE) -> 46328
A25: UC-21 | B25: Gợi ý ghép đơn–chuyến | C25: MKT | D25: Hệ thống | E25: Người giao, Người gửi | F25: Should | G25: Pha 2 | H25: Có chuyến đi và đơn đang mở. | I25: Danh sách gợi ý được tạo và hiển thị. | J25: 1. Hệ thống tải chuyến đi và đơn mở 2. Tính khoảng cách lệch tuyến và độ phù hợp thời gian 3. Chấm điểm phù hợp và xếp hạng 4. Hiển thị gợi ý cho người giao và người gửi 5. Cho phép nhận hoặc chào giá nhanh | K25: • A1 Không có đơn trong độ lệch cho phép: không gợi ý | L25: BR-F-034, BR-F-038, BR-N-008, BR-R-036, BR-G-008 | M25: SCR-34 | N25: =COUNTIF('10_API'!$G:$G,A25) -> 2 | O25: =VLOOKUP(A25, '15_Chia task(UC)'!$D$7:$G$69, 3, FALSE) -> Võ Quốc An | P25: =VLOOKUP(A25, '15_Chia task(UC)'!$D$7:$G$69, 4, FALSE) -> Sprint 4 | Q25: =IF(O25="Trần Công Thuận", 6, 8) -> 8 | R25: Dự thảo | S25: =VLOOKUP(A25, '15_Chia task(UC)'!$D$7:$I$69, 5, FALSE) -> 46322 | T25: =VLOOKUP(A25, '15_Chia task(UC)'!$D$7:$I$69, 6, FALSE) -> 46328
A26: UC-22 | B26: Đăng chuyến đi | C26: TRP | D26: Người giao | E26: Dịch vụ Bản đồ | F26: Should | G26: Pha 2 | H26: Người giao đã được duyệt. | I26: Chuyến đi được tạo. | J26: 1. Người giao nhập điểm đi, điểm đến, giờ khởi hành 2. Chọn phương tiện, sức chứa, giá sàn 3. Hệ thống tính tuyến đường 4. Lưu chuyến và kích hoạt gợi ý ghép | K26: • A1 Chuyến định kỳ (Could): sinh các lần khởi hành | L26: BR-F-036, BR-F-037, BR-F-038, BR-R-035, BR-G-008 | M26: SCR-33 | N26: =COUNTIF('10_API'!$G:$G,A26) -> 2 | O26: =VLOOKUP(A26, '15_Chia task(UC)'!$D$7:$G$69, 3, FALSE) -> Võ Quốc An | P26: =VLOOKUP(A26, '15_Chia task(UC)'!$D$7:$G$69, 4, FALSE) -> Sprint 3 | Q26: =IF(O26="Trần Công Thuận", 6, 8) -> 8 | R26: Dự thảo | S26: =VLOOKUP(A26, '15_Chia task(UC)'!$D$7:$I$69, 5, FALSE) -> 46315 | T26: =VLOOKUP(A26, '15_Chia task(UC)'!$D$7:$I$69, 6, FALSE) -> 46321
A27: UC-23 | B27: Quản lý chuyến đi | C27: TRP | D27: Người giao | F27: Should | G27: Pha 2 | H27: Có chuyến đi. | I27: Chuyến được cập nhật/hủy/kết thúc. | J27: 1. Người giao mở danh sách chuyến 2. Sửa, tạm dừng nhận đơn, hủy hoặc kết thúc 3. Hệ thống kiểm tra quy tắc chuyến có đơn | K27: • A1 Chuyến có đơn đã chọn: không hủy trực tiếp | L27: BR-F-039, BR-F-040, BR-R-037 | M27: SCR-34 | N27: =COUNTIF('10_API'!$G:$G,A27) -> 5 | O27: =VLOOKUP(A27, '15_Chia task(UC)'!$D$7:$G$69, 3, FALSE) -> Võ Quốc An | P27: =VLOOKUP(A27, '15_Chia task(UC)'!$D$7:$G$69, 4, FALSE) -> Sprint 3 | Q27: =IF(O27="Trần Công Thuận", 6, 8) -> 8 | R27: Dự thảo | S27: =VLOOKUP(A27, '15_Chia task(UC)'!$D$7:$I$69, 5, FALSE) -> 46315 | T27: =VLOOKUP(A27, '15_Chia task(UC)'!$D$7:$I$69, 6, FALSE) -> 46321
A28: UC-24 | B28: Chat theo đơn | C28: NEG | D28: Người dùng | F28: Must | G28: Pha 1 | H28: Đơn có chào giá hoặc đã có người giao. | I28: Tin nhắn được gửi và lưu. | J28: 1. Người dùng mở phòng chat của đơn 2. Hệ thống nạp lịch sử 3. Người dùng gửi tin nhắn hoặc ảnh 4. Hệ thống kiểm tra mẫu thông tin liên hệ, lưu MongoDB, đẩy cho bên kia 5. Cập nhật đã đọc | K28: • A1 Tin nhắn chứa SĐT/tài khoản trước khi chọn người giao: che và cảnh báo • A2 Báo cáo tin nhắn: UC-55 | L28: BR-F-041, BR-F-042, BR-F-043, BR-F-044, BR-F-045, BR-N-011, BR-R-033, BR-R-034, BR-C-004 | M28: SCR-38 | N28: =COUNTIF('10_API'!$G:$G,A28) -> 4 | O28: =VLOOKUP(A28, '15_Chia task(UC)'!$D$7:$G$69, 3, FALSE) -> Huỳnh Phi Long | P28: =VLOOKUP(A28, '15_Chia task(UC)'!$D$7:$G$69, 4, FALSE) -> Sprint 1 | Q28: =IF(O28="Trần Công Thuận", 6, 8) -> 8 | R28: Dự thảo | S28: =VLOOKUP(A28, '15_Chia task(UC)'!$D$7:$I$69, 5, FALSE) -> 46305 | T28: =VLOOKUP(A28, '15_Chia task(UC)'!$D$7:$I$69, 6, FALSE) -> 46307
A29: UC-25 | B29: Xác nhận lấy hàng (QR + ảnh) | C29: TRK | D29: Người giao | E29: Người gửi | F29: Must | G29: Pha 1 | H29: Đơn Đã ký quỹ. | I29: Đơn chuyển Đã lấy hàng. | J29: 1. Người giao đến điểm lấy, mở Lấy hàng 2. Người gửi hiển thị mã QR lấy hàng 3. Người giao quét/nhập mã 4. Người giao chụp ảnh hàng 5. Hệ thống chuyển trạng thái, bắt đầu chia sẻ vị trí, thông báo | K29: • A1 Mã sai/hết hạn: làm mới mã • A2 Quá hạn lấy hàng: hệ thống xử lý theo UC-63 | L29: BR-F-046, BR-F-047, BR-F-123, BR-N-023, BR-R-038, BR-G-009 | M29: SCR-24, SCR-32 | N29: =COUNTIF('10_API'!$G:$G,A29) -> 2 | O29: =VLOOKUP(A29, '15_Chia task(UC)'!$D$7:$G$69, 3, FALSE) -> Huỳnh Phi Long | P29: =VLOOKUP(A29, '15_Chia task(UC)'!$D$7:$G$69, 4, FALSE) -> Sprint 3 | Q29: =IF(O29="Trần Công Thuận", 6, 8) -> 8 | R29: Dự thảo | S29: =VLOOKUP(A29, '15_Chia task(UC)'!$D$7:$I$69, 5, FALSE) -> 46315 | T29: =VLOOKUP(A29, '15_Chia task(UC)'!$D$7:$I$69, 6, FALSE) -> 46321
A30: UC-26 | B30: Chia sẻ vị trí và cập nhật hành trình | C30: TRK | D30: Người giao | F30: Must | G30: Pha 1 | H30: Đơn Đã lấy hàng/Đang giao. | I30: Điểm vị trí và mốc hành trình được lưu. | J30: 1. Người giao cấp quyền vị trí 2. Ứng dụng gửi vị trí theo chu kỳ 3. Hệ thống lưu MongoDB và đẩy tới người theo dõi 4. Người giao cập nhật mốc Đang giao, Đã đến điểm giao | K30: • A1 Không có quyền vị trí: chặn chuyển trạng thái và hướng dẫn • A2 Mất mạng: gửi bù khi có lại • A3 Đứng yên/lệch tuyến: cảnh báo (Could) | L30: BR-F-048, BR-F-049, BR-F-056, BR-N-007, BR-R-041, BR-C-017 | M30: SCR-32 | N30: =COUNTIF('10_API'!$G:$G,A30) -> 2 | O30: =VLOOKUP(A30, '15_Chia task(UC)'!$D$7:$G$69, 3, FALSE) -> Huỳnh Phi Long | P30: =VLOOKUP(A30, '15_Chia task(UC)'!$D$7:$G$69, 4, FALSE) -> Sprint 1 | Q30: =IF(O30="Trần Công Thuận", 6, 8) -> 8 | R30: Dự thảo | S30: =VLOOKUP(A30, '15_Chia task(UC)'!$D$7:$I$69, 5, FALSE) -> 46305 | T30: =VLOOKUP(A30, '15_Chia task(UC)'!$D$7:$I$69, 6, FALSE) -> 46307
A31: UC-27 | B31: Theo dõi đơn thời gian thực | C31: TRK | D31: Người gửi | E31: Người nhận | F31: Must | G31: Pha 1 | H31: Đơn đang giao hoặc có liên kết theo dõi. | I31: Hiển thị vị trí, timeline, ETA. | J31: 1. Người gửi hoặc người nhận mở màn hình theo dõi 2. Hệ thống nạp timeline và vị trí gần nhất 3. Nhận cập nhật qua WebSocket 4. Hiển thị bản đồ, ETA, trạng thái | K31: • A1 Người nhận mở liên kết công khai: chỉ thấy thông tin tối thiểu • A2 Liên kết hết hạn: thông báo | L31: BR-F-022, BR-F-050, BR-F-051, BR-F-062, BR-F-122, BR-N-007, BR-N-011, BR-R-042, BR-C-004 | M31: SCR-09, SCR-23 | N31: =COUNTIF('10_API'!$G:$G,A31) -> 3 | O31: =VLOOKUP(A31, '15_Chia task(UC)'!$D$7:$G$69, 3, FALSE) -> Huỳnh Phi Long | P31: =VLOOKUP(A31, '15_Chia task(UC)'!$D$7:$G$69, 4, FALSE) -> Sprint 2 | Q31: =IF(O31="Trần Công Thuận", 6, 8) -> 8 | R31: Dự thảo | S31: =VLOOKUP(A31, '15_Chia task(UC)'!$D$7:$I$69, 5, FALSE) -> 46308 | T31: =VLOOKUP(A31, '15_Chia task(UC)'!$D$7:$I$69, 6, FALSE) -> 46314
A32: UC-28 | B32: Xác nhận giao hàng (OTP/QR + ảnh) | C32: TRK | D32: Người giao | E32: Người nhận | F32: Must | G32: Pha 1 | H32: Đơn Đang giao, người giao đã đến điểm giao. | I32: Đơn Đã giao; bắt đầu đếm giải ngân. | J32: 1. Hệ thống gửi OTP cho người nhận 2. Người nhận đưa OTP hoặc QR 3. Người giao nhập/quét và chụp ảnh giao 4. Hệ thống kiểm tra, chuyển Đã giao, ngừng chia sẻ vị trí 5. Thông báo người gửi và đặt lịch giải ngân | K32: • A1 OTP sai: tăng đếm, khóa khi quá số lần • A2 Người nhận không có OTP: giao ngoại lệ kèm ảnh, tọa độ, lý do • A3 Người nhận vắng: UC-30 | L32: BR-F-052, BR-F-053, BR-F-103, BR-F-123, BR-N-027, BR-R-039, BR-R-040, BR-G-004, BR-G-009 | M32: SCR-32 | N32: =COUNTIF('10_API'!$G:$G,A32) -> 3 | O32: =VLOOKUP(A32, '15_Chia task(UC)'!$D$7:$G$69, 3, FALSE) -> Huỳnh Phi Long | P32: =VLOOKUP(A32, '15_Chia task(UC)'!$D$7:$G$69, 4, FALSE) -> Sprint 2 | Q32: =IF(O32="Trần Công Thuận", 6, 8) -> 8 | R32: Dự thảo | S32: =VLOOKUP(A32, '15_Chia task(UC)'!$D$7:$I$69, 5, FALSE) -> 46308 | T32: =VLOOKUP(A32, '15_Chia task(UC)'!$D$7:$I$69, 6, FALSE) -> 46314
A33: UC-29 | B33: Báo sự cố khi giao | C33: TRK | D33: Người giao | E33: Người gửi, Kiểm duyệt | F33: Must | G33: Pha 1 | H33: Đơn đã Đã lấy hàng/Đang giao. | I33: Sự cố được ghi nhận, các bên được thông báo. | J33: 1. Người giao chọn Báo sự cố 2. Chọn loại sự cố, mô tả, ảnh 3. Hệ thống ghi vào timeline 4. Thông báo người gửi và Kiểm duyệt | K33: • A1 SOS khẩn cấp: cảnh báo ưu tiên kèm vị trí | L33: BR-F-054, BR-F-110 | M33: SCR-32 | N33: =COUNTIF('10_API'!$G:$G,A33) -> 2 | O33: =VLOOKUP(A33, '15_Chia task(UC)'!$D$7:$G$69, 3, FALSE) -> Huỳnh Phi Long | P33: =VLOOKUP(A33, '15_Chia task(UC)'!$D$7:$G$69, 4, FALSE) -> Sprint 3 | Q33: =IF(O33="Trần Công Thuận", 6, 8) -> 8 | R33: Dự thảo | S33: =VLOOKUP(A33, '15_Chia task(UC)'!$D$7:$I$69, 5, FALSE) -> 46315 | T33: =VLOOKUP(A33, '15_Chia task(UC)'!$D$7:$I$69, 6, FALSE) -> 46321
A34: UC-30 | B34: Giao thất bại và hoàn hàng | C34: TRK | D34: Người giao | E34: Người gửi | F34: Must | G34: Pha 1 | H34: Đơn Đang giao; không giao được. | I34: Đơn Đang hoàn rồi Đã hoàn hàng. | J34: 1. Người giao ghi nhận không liên lạc được người nhận 2. Hệ thống kiểm tra bằng chứng liên hệ 3. Đơn chuyển Giao thất bại rồi Đang hoàn 4. Người giao trả hàng, người gửi xác nhận bằng mã 5. Hệ thống tính phí giao và phí hoàn | K34: • A1 Người nhận liên lạc lại: tiếp tục giao | L34: BR-F-055, BR-R-044 | M34: SCR-24, SCR-32 | N34: =COUNTIF('10_API'!$G:$G,A34) -> 2 | O34: =VLOOKUP(A34, '15_Chia task(UC)'!$D$7:$G$69, 3, FALSE) -> Huỳnh Phi Long | P34: =VLOOKUP(A34, '15_Chia task(UC)'!$D$7:$G$69, 4, FALSE) -> Sprint 4 | Q34: =IF(O34="Trần Công Thuận", 6, 8) -> 8 | R34: Dự thảo | S34: =VLOOKUP(A34, '15_Chia task(UC)'!$D$7:$I$69, 5, FALSE) -> 46322 | T34: =VLOOKUP(A34, '15_Chia task(UC)'!$D$7:$I$69, 6, FALSE) -> 46328
A35: UC-31 | B35: Gộp đơn và gợi ý lộ trình | C35: REL | D35: Người giao | F35: Could | G35: Pha 3 | H35: Người giao có từ 2 đơn trở lên. | I35: Lượt giao gộp được tạo. | J35: 1. Người giao chọn các đơn cùng tuyến 2. Hệ thống kiểm tra giới hạn gộp 3. Hệ thống tính thứ tự điểm dừng 4. Người giao xác nhận lộ trình | K35: • A1 Vượt giới hạn số đơn/sức chứa: từ chối | L35: BR-F-057, BR-F-058, BR-R-046 | M35: SCR-36 | N35: =COUNTIF('10_API'!$G:$G,A35) -> 2 | O35: =VLOOKUP(A35, '15_Chia task(UC)'!$D$7:$G$69, 3, FALSE) -> Võ Quốc An | P35: =VLOOKUP(A35, '15_Chia task(UC)'!$D$7:$G$69, 4, FALSE) -> Sprint 5 | Q35: =IF(O35="Trần Công Thuận", 6, 8) -> 8 | R35: Dự thảo | S35: =VLOOKUP(A35, '15_Chia task(UC)'!$D$7:$I$69, 5, FALSE) -> 46329 | T35: =VLOOKUP(A35, '15_Chia task(UC)'!$D$7:$I$69, 6, FALSE) -> 46339
A36: UC-32 | B36: Tạo đơn giao tiếp sức | C36: REL | D36: Người gửi | E36: Người giao | F36: Could | G36: Pha 3 | H36: Tuyến đủ dài và đủ điều kiện chia chặng. | I36: Đơn có nhiều chặng ở trạng thái Đang mở theo chặng. | J36: 1. Người gửi chọn Giao tiếp sức 2. Hệ thống đề xuất điểm bàn giao và chặng 3. Người gửi xác nhận, hệ thống chia phí theo quãng đường 4. Mỗi chặng lên sàn riêng | K36: • A1 Không đủ người giao cho chặng: giữ đơn mở | L36: BR-F-059, BR-F-062, BR-R-047 | N36: =COUNTIF('10_API'!$G:$G,A36) -> 1 | O36: =VLOOKUP(A36, '15_Chia task(UC)'!$D$7:$G$69, 3, FALSE) -> Nguyễn Thành Huy | P36: =VLOOKUP(A36, '15_Chia task(UC)'!$D$7:$G$69, 4, FALSE) -> Sprint 4 | Q36: =IF(O36="Trần Công Thuận", 6, 8) -> 8 | R36: Dự thảo | S36: =VLOOKUP(A36, '15_Chia task(UC)'!$D$7:$I$69, 5, FALSE) -> 46322 | T36: =VLOOKUP(A36, '15_Chia task(UC)'!$D$7:$I$69, 6, FALSE) -> 46328
A37: UC-33 | B37: Bàn giao giữa các chặng | C37: REL | D37: Người giao | F37: Could | G37: Pha 3 | H37: Đơn tiếp sức có chặng kế tiếp. | I37: Trách nhiệm chuyển sang người giao kế tiếp. | J37: 1. Hai người giao gặp nhau tại điểm hẹn 2. Người giao kế tiếp quét QR bàn giao 3. Hai bên chụp ảnh hàng 4. Hệ thống xác nhận, bắt đầu chặng tiếp theo | K37: • A1 QR hết hạn: làm mới • A2 Bàn giao không thành: sự cố | L37: BR-F-060, BR-F-061, BR-R-048 | N37: =COUNTIF('10_API'!$G:$G,A37) -> 1 | O37: =VLOOKUP(A37, '15_Chia task(UC)'!$D$7:$G$69, 3, FALSE) -> Võ Quốc An | P37: =VLOOKUP(A37, '15_Chia task(UC)'!$D$7:$G$69, 4, FALSE) -> Sprint 5 | Q37: =IF(O37="Trần Công Thuận", 6, 8) -> 8 | R37: Dự thảo | S37: =VLOOKUP(A37, '15_Chia task(UC)'!$D$7:$I$69, 5, FALSE) -> 46329 | T37: =VLOOKUP(A37, '15_Chia task(UC)'!$D$7:$I$69, 6, FALSE) -> 46336
